<?xml version="1.0" ?>
<robot name="rubot_arm">
    <link name="world" />
    <link name="base_link">
        <visual>
            <geometry>
                <cylinder length="0.05" radius="0.1" />
            </geometry>
            <material name="silver">
                <color rgba="0.75 0.75 0.75 1" />
            </material>
            <origin rpy="0 0 0" xyz="0 0 0.025" />
        </visual>
        <collision>
            <geometry>
                <cylinder length="0.05" radius="0.1" />
            </geometry>
            <origin rpy="0 0 0" xyz="0 0 0.025" />
        </collision>
        
<inertial>
            <mass value="1.0" />
            <origin rpy="0 0 0" xyz="0 0 0.025" />
            <inertia ixx="0.0027" iyy="0.0027" izz="0.005" ixy="0" ixz="0" iyz="0" />
        </inertial>

    </link>
    <joint name="fixed" type="fixed">
        <parent link="world" />
        <child link="base_link" />
    </joint>
    <link name="One">
        <visual>
            <geometry>
                <cylinder length="0.5" radius="0.05" />
            </geometry>
            <material name="silver">
                <color rgba="0.75 0.75 0.75 1" />
            </material>
            <origin rpy="0 0 0" xyz="0 0 0.25" />
        </visual>
        <collision>
            <geometry>
                <cylinder length="0.5" radius="0.05" />
            </geometry>
            <origin rpy="0 0 0" xyz="0 0 0.25" />
        </collision>
        
<inertial>
            <mass value="1.0" />
            <origin rpy="0 0 0" xyz="0 0 0.25" />
            <inertia ixx="0.02146" iyy="0.02146" izz="0.00125" ixy="0" ixz="0" iyz="0" />
        </inertial>

    </link>
    <joint name="One_joint" type="continuous">
        <axis xyz="0 0 1" />
        <parent link="base_link" />
        <child link="One" />
        <origin rpy="0 0 0" xyz="0.0 0.0 0.05" />
    </joint>
    <link name="Two">
        <visual>
            <geometry>
                <cylinder length="0.4" radius="0.05" />
            </geometry>
            <material name="silver" />
            <origin rpy="0 0 0" xyz="0 0 0.2" />
        </visual>
        <collision>
            <geometry>
                <cylinder length="0.4" radius="0.05" />
            </geometry>
            <origin rpy="0 0 0" xyz="0 0 0.2" />
        </collision>
        
<inertial>
            <mass value="1.0" />
            <origin rpy="0 0 0" xyz="0 0 0.2" />
            <inertia ixx="0.01396" iyy="0.01396" izz="0.00125" ixy="0" ixz="0" iyz="0" />
        </inertial>

    </link>
    <joint name="Two_joint" type="continuous">
        <axis xyz="0 1 0" />
        <parent link="One" />
        <child link="Two" />
        <origin rpy="0 1.5708 0" xyz="0.0 -0.1 0.45" />
    </joint>
    <link name="Three">
        <visual>
            <geometry>
                <cylinder length="0.4" radius="0.05" />
            </geometry>
            <material name="silver" />
            <origin rpy="0 0 0" xyz="0 0 0.2" />
        </visual>
        <collision>
            <geometry>
                <cylinder length="0.4" radius="0.05" />
            </geometry>
            <origin rpy="0 0 0" xyz="0 0 0.2" />
        </collision>
        
<inertial>
            <mass value="1.0" />
            <origin rpy="0 0 0" xyz="0 0 0.2" />
            <inertia ixx="0.01396" iyy="0.01396" izz="0.00125" ixy="0" ixz="0" iyz="0" />
        </inertial>

    </link>
    <joint name="Three_joint" type="continuous">
        <axis xyz="0 1 0" />
        <parent link="Two" />
        <child link="Three" />
        <origin rpy="0 0 0" xyz="0.0 0.1 0.35" />
    </joint>
    <link name="Four">
        <visual>
            <geometry>
                <box size="0.05 0.05 0.05" />
            </geometry>
            <material name="silver" />
        </visual>
        <collision>
            <geometry>
                <box size="0.05 0.05 0.05" />
            </geometry>
        </collision>
        
<inertial>
            <mass value="1.0" />
            <inertia ixx="0.00042" iyy="0.00042" izz="0.00042" ixy="0" ixz="0" iyz="0" />
        </inertial>

    </link>
    <joint name="Four_joint" type="continuous">
        <axis xyz="0 1 0" />
        <parent link="Three" />
        <child link="Four" />
        <origin rpy="0 0 0" xyz="0.0 0.0 0.425" />
    </joint>
    
<transmission name="trans_One_joint">
        <type>transmission_interface/SimpleTransmission</type>
        <joint name="One_joint">
            <hardwareInterface>hardware_interface/PositionJointInterface</hardwareInterface>
        </joint>
        <actuator name="One_joint_motor">
            <hardwareInterface>hardware_interface/PositionJointInterface</hardwareInterface>
            <mechanicalReduction>1</mechanicalReduction>
        </actuator>
    </transmission>
    <transmission name="trans_Two_joint">
        <type>transmission_interface/SimpleTransmission</type>
        <joint name="Two_joint">
            <hardwareInterface>hardware_interface/PositionJointInterface</hardwareInterface>
        </joint>
        <actuator name="Two_joint_motor">
            <hardwareInterface>hardware_interface/PositionJointInterface</hardwareInterface>
            <mechanicalReduction>1</mechanicalReduction>
        </actuator>
    </transmission>
    <transmission name="trans_Three_joint">
        <type>transmission_interface/SimpleTransmission</type>
        <joint name="Three_joint">
            <hardwareInterface>hardware_interface/PositionJointInterface</hardwareInterface>
        </joint>
        <actuator name="Three_joint_motor">
            <hardwareInterface>hardware_interface/PositionJointInterface</hardwareInterface>
            <mechanicalReduction>1</mechanicalReduction>
        </actuator>
    </transmission>
    <transmission name="trans_Four_joint">
        <type>transmission_interface/SimpleTransmission</type>
        <joint name="Four_joint">
            <hardwareInterface>hardware_interface/PositionJointInterface</hardwareInterface>
        </joint>
        <actuator name="Four_joint_motor">
            <hardwareInterface>hardware_interface/PositionJointInterface</hardwareInterface>
            <mechanicalReduction>1</mechanicalReduction>
        </actuator>
    </transmission>
    <gazebo>
        <plugin name="gazebo_ros_control" filename="libgazebo_ros_control.so">
            <robotNamespace>/</robotNamespace>
        </plugin>
    </gazebo>
</robot>